Workbook

Sheet BS
A1: PROGEN RENEWABLES LIMITED
A2: 87 A, First Floor, Sathy Road, Muniappan Koil Street, Ganapathy, Coimbatore,Tamil Nadu - 641 006.
A3: CIN : U31909TZ2017PLC029803
A4: Balance Sheet as at 31st March 2025
A5: (Rupees in 000's)
A6: Particulars | C6: Note No. | D6: For the year ended March 31, 2025 | E6: For the year ended March 31, 2024 | F6: Difference | G6: For the year ended March 31, 2023 | H6: Difference
A7: I | B7: EQUITY AND LIABILITIES:
A8: 1 | B8: Shareholders' Funds:
B9: a. Share Capital | C9: 1 | D9: =+'Note 4 - SOCES'!E12 -> 1872240 | E9: =+'Note 4 - SOCES'!G12 -> 1666670 | F9: =+D9-E9 -> 205570 | G9: =+'Note 4 - SOCES'!I12 -> 1000000 | H9: =+E9-G9 -> 666670
B10: b. Reserves and Surplus | C10: 2 | D10: =+'Notes - '!D17 -> 451037991 | E10: =+'Notes - '!F17 -> 118616293 | F10: =+D10-E10 -> 332421698 | G10: =+'Notes - '!H17 -> 34498048 | H10: =+E10-G10 -> 84118245
F11: =+D11-E11 -> 0
A12: 2 | B12: Non-Current Liabilities:
B13: a. Long-Term Borrowings | C13: 3 | D13: =+'Notes - '!D24 -> 2208945 | E13: =+'Notes - '!F24 -> 2051790 | F13: =+D13-E13 -> 157155 | G13: =+'Notes - '!H24 -> 3036391 | H13: =+E13-G13 -> -984601
B14: b. Deferred Tax Liabilities (Net) | C14: 4 | D14: 0 | E14: =+'Notes - '!F44 -> 225648 | F14: =+D14-E14 -> -225648 | G14: =+'Notes - '!H44 -> 162653 | H14: =+E14-G14 -> 62995
B15: c. Long term Provisions | C15: 5 | D15: =+'Notes - '!D50 -> 1204777 | E15: =+'Notes - '!F50 -> 0
A17: 3 | B17: Current Liabilities:
B18: a. Short-Term Borrowings | C18: 6 | D18: =+'Notes - '!D61 -> 60363589 | E18: =+'Notes - '!F61 -> 38551261 | F18: =+D18-E18 -> 21812328 | G18: =+'Notes - '!H61 -> 10128093 | H18: =+E18-G18 -> 28423168
B19: b. Trade Payables | C19: 7 | D19: =+'Notes - '!D82 -> 205494089 | E19: =+'Notes - '!F82 -> 120573466 | F19: =+D19-E19 -> 84920623 | G19: =+'Notes - '!H82 -> 44810024 | H19: =+E19-G19 -> 75763442
B20: c. Other Current Liabilities | C20: 8 | D20: =+'Notes - '!D122 -> 216932355 | E20: =+'Notes - '!F122 -> 155839042 | F20: =+D20-E20 -> 61093313 | G20: =+'Notes - '!H122 -> 334053244 | H20: =+E20-G20 -> -178214202
B21: d. Short-Term Provisions | C21: 9 | D21: =+'Notes - '!D136 -> 48149163 | E21: =+'Notes - '!F136 -> 31290496 | F21: =+D21-E21 -> 16858667 | G21: =+'Notes - '!H136 -> 6187513 | H21: =+E21-G21 -> 25102983
B22: Total | D22: =SUM(D9:D21) -> 987263149 | E22: =SUM(E9:E21) -> 468814666 | F22: =SUM(F7:F21) -> 517243706 | G22: =SUM(G7:G21) -> 433875966 | H22: =SUM(H7:H21) -> 34938700
A23: II | B23: ASSETS
A24: 1 | B24: Non-Current Assets:
B25: a. Property, Plant & Equipments | C25: 10
B26: i. Tangible Assets | D26: =+Notes!M19 -> 16224913 | E26: =+Notes!L19 -> 9013798 | F26: =+E26-D26 -> -7211115 | G26: =+Notes!N19 -> 7709135 | H26: =+G26-E26 -> -1304663
B27: ii. Intangible Assets | D27: =+Notes!M22 -> 128414 | E27: =+Notes!L22 -> 175906 | F27: =+E27-D27 -> 47492 | G27: =+Notes!N22 -> 0 | H27: =+G27-E27 -> -175906
B29: b. Deferred Tax Assets (Net) | C29: 4 | D29: =-'Notes - '!D44:E44 -> 1531798 | E29: 0 | F29: =+E29-D29 -> -1531798 | G29: 0 | H29: =+G29-E29 -> 0
B30: c. Long-Term Loans & Advances | C30: 11 | D30: =+'Notes -'!F10 -> 109000 | E30: =+'Notes -'!H10 -> 740000 | F30: =+E30-D30 -> 631000 | G30: =+'Notes -'!J10 -> 740000 | H30: =+G30-E30 -> 0
B31: d. Other Non-Current Assets | C31: 12 | D31: =+'Notes -'!F18 -> 47000000 | E31: =+'Notes -'!H18 -> 10000000 | F31: =+E31-D31 -> -37000000 | G31: =+'Notes -'!J18 -> 0 | H31: =+G31-E31 -> -10000000
A33: 2 | B33: Current Assets:
B34: a. Inventories | C34: 13 | D34: =+'Notes -'!F25 -> 38325985 | E34: =+'Notes -'!H25 -> 117014200 | F34: =+E34-D34 -> 78688215 | G34: =+'Notes -'!J25 -> 257149228 | H34: =+G34-E34 -> 140135028
B35: b. Trade Receivables | C35: 14 | D35: =+'Notes -'!F35 -> 700374795 | E35: =+'Notes -'!H35 -> 246523964 | F35: =+E35-D35 -> -453850831 | G35: =+'Notes -'!J35 -> 77497655 | H35: =+G35-E35 -> -169026309
B36: c. Cash & Cash Equivalents | C36: 15 | D36: =+'Notes -'!F75 -> 27671325 | E36: =+'Notes -'!H75 -> 9682573 | F36: =+E36-D36 -> -17988752 | G36: =+'Notes -'!J75 -> 6827 | H36: =+G36-E36 -> -9675746
B37: d. Short-Term Loans & Advances | C37: 16 | D37: =+'Notes -'!F100 -> 140013589 | E37: =+'Notes -'!H100 -> 70446641 | F37: =+E37-D37 -> -69566948 | G37: =+'Notes -'!J100 -> 77667873 | H37: =+G37-E37 -> 7221232
B38: e. Other Current Assets | C38: 17 | D38: =+'Notes -'!F111 -> 15883330 | E38: =+'Notes -'!H111 -> 5217584 | F38: =+E38-D38 -> -10665746 | G38: =+'Notes -'!J111 -> 13105248 | H38: =+G38-E38 -> 7887664
B39: Total | D39: =SUM(D26:D38) -> 987263149 | E39: =SUM(E26:E38) -> 468814666 | F39: =SUM(F26:F38) -> -518448483 | G39: =SUM(G26:G38) -> 433875966 | H39: =SUM(H26:H38) -> -34938700
B40: Significant Accounting Policies | C40: 28
A42: The Accompanying Notes 1 - 46 are an Integral Part of Financial Statements
A43: As Per our Report of even date Attached
A45: For S.P.P & Co | C45: For and On behalf of the Board of Directors of
...

Sheet P&L
A1: =+BS!A1 -> PROGEN RENEWABLES LIMITED
A2: =+BS!A2 -> 87 A, First Floor, Sathy Road, Muniappan Koil Street, Ganapathy, Coimbatore,Tamil Nadu - 641 006.
A3: =+BS!A3 -> CIN : U31909TZ2017PLC029803
A4: Profit and Loss Statement for the year ended 31st March 2025
A5: (Rupees in 000's)
A6: Particulars | C6: Note No. | D6: For the year ended March 31, 2025 | E6: For the year ended March 31, 2024 | F6: For the year ended March 31, 2023
A7: I. | B7: Revenue from Operations | C7: 18 | D7: =+'Notes-P&L'!C9 -> 1346412261 | E7: =+'Notes-P&L'!D13 -> 1116291072 | F7: =+'Notes-P&L'!E9 -> 565057844
A8: II. | B8: Other Income | C8: 19 | D8: =+'Notes-P&L'!C23 -> 876508 | E8: =+'Notes-P&L'!D23 -> 338274 | F8: =+'Notes-P&L'!E23 -> 0
A9: III. | B9: TOTAL INCOME (I+II) | D9: =SUM(D7:D8) -> 1347288769 | E9: =SUM(E7:E8) -> 1116629346 | F9: =SUM(F7:F8) -> 565057844
A10: IV. | B10: EXPENSES : -
B11: a. Purchase of Stock | C11: 20 | D11: =+'Notes-P&L'!C32 -> 713272184 | E11: =+'Notes-P&L'!D32 -> 690532439 | F11: =+'Notes-P&L'!E32 -> 321635156
B12: b. Changes in inventories of FG, WIP & SIT | C12: 21 | D12: =+'Notes-P&L'!C43 -> 78688215 | E12: =+'Notes-P&L'!D43 -> 140135028 | F12: =+'Notes-P&L'!E43 -> 160557822
B13: c. Employee Benefits Expense | C13: 22 | D13: =+'Notes-P&L'!C60 -> 28640681 | E13: =+'Notes-P&L'!D60 -> 11611968 | F13: =+'Notes-P&L'!E60 -> 16958565
B14: d. Finance Costs | C14: 23 | D14: =+'Notes-P&L'!C68 -> 2636496 | E14: =+'Notes-P&L'!D68 -> 2042977 | F14: =+'Notes-P&L'!E68 -> 289520
B15: e. Depreciation & Amortization Expense | C15: 24 | D15: =+'Notes-P&L'!C75 -> 1813010 | E15: =+'Notes-P&L'!D75 -> 1079988 | F15: =+'Notes-P&L'!E75 -> 905315
B16: f. Other Expenses | C16: 25 | D16: =+'Notes-P&L'!C152 -> 346631113 | E16: =+'Notes-P&L'!D152 -> 162397976 | F16: =+'Notes-P&L'!E152 -> 49699327
B17: TOTAL EXPENSES (IV) | D17: =SUM(D11:D16) -> 1171681699 | E17: =SUM(E11:E16) -> 1007800376 | F17: =SUM(F11:F16) -> 550045705
A18: V. | B18: Profit before Exceptional & Extraordinary and
B19: Prior Period Items and Tax (III-IV) | D19: =+D9-D17 -> 175607070 | E19: =+E9-E17 -> 108828970 | F19: =+F9-F17 -> 15012139
A20: VI. | B20: Exceptional Items | D20: 0 | E20: 0 | F20: 0
A21: VII. | B21: Profit before Extraordinary & Prior Period Items | D21: =+D19-D20 -> 175607070 | E21: =+E19-E20 -> 108828970 | F21: =+F19-F20 -> 15012139
B22: and Tax (V-VI)
B23: a. Extraordinary Items | D23: 0 | E23: 0 | F23: 0
B24: b. Prior Period Items | C24: 34 | D24: =4823150-183832 -> 4639318 | E24: 0 | F24: 0
A25: VIII. | B25: PROFIT BEFORE TAX (VII-VIII) | D25: =+D21-D23-D24 -> 170967752 | E25: =+E21-E23 -> 108828970 | F25: =+F21-F23 -> 15012139
A26: IX | B26: TAX EXPENSES : - | C26: 31
B27: 1. Current Tax | D27: =+Sheet1!E18 -> 46429720 | E27: 27635821 | F27: 0
B28: 2. Provision for tax related to earlier year | D28: 0 | E28: 9545305 | F28: 0
B29: 3. Deferred Tax (Income) / Expenses | D29: =+'Notes - '!D42:E42 -> -1757446 | E29: 62995 | F29: 102745
D30: =SUM(D27:D29) -> 44672274 | E30: =SUM(E27:E29) -> 37244121 | F30: =SUM(F27:F29) -> 102745
A31: X. | B31: Profit (Loss) for the period from Continuing | D31: =+D25-D30 -> 126295478 | E31: =+E25-E30 -> 71584849 | F31: =+F25-F30 -> 14909394
B32: Operations (VIII-IX)
A33: XI. | B33: Profit (Loss) for the Period | D33: =SUM(D31:D32) -> 126295478 | E33: =SUM(E31:E32) -> 71584849 | F33: =SUM(F31:F32) -> 14909394
A34: XII. | B34: Earnings per Equity Share:
B35: 1. Basic | C35: 33 | D35: =+D33/'Note 4 - SOCES'!D22 -> 674.56885 | E35: =+E33/'Note 4 - SOCES'!F22 -> 429.50823 | F35: =+F33/'Note 4 - SOCES'!H22 -> 149.09394
B36: 2. Diluted | C36: 33 | D36: =+D33/'Note 4 - SOCES'!D22 -> 674.56885 | E36: =+E33/'Note 4 - SOCES'!F22 -> 429.50823 | F36: =+F33/'Note 4 - SOCES'!H22 -> 149.09394
A38: =+BS!A42 -> The Accompanying Notes 1 - 46 are an Integral Part of Financial Statements
A39: =+BS!A43 -> As Per our Report of even date Attached
A41: For S.P.P & Co | C41: For and on behalf of the Board of directors of
A42: Chartered Accountants | C42: =+BS!A1 -> PROGEN RENEWABLES LIMITED
...

Sheet CFS
A1: =+BS!A1 -> PROGEN RENEWABLES LIMITED
A2: =+BS!A2 -> 87 A, First Floor, Sathy Road, Muniappan Koil Street, Ganapathy, Coimbatore,Tamil Nadu - 641 006.
A3: =+BS!A3 -> CIN : U31909TZ2017PLC029803
A4: Cash Flow Statement for the period ending 31st March, 2025
A5: (Rupees in 000's)
A6: Particulars | D6: For the year ended March 31, 2025 | E6: For the year ended March 31, 2024
A7: A | B7: CASH FLOW FROM OPERATING ACTIVITIES:
B8: Net Profit / (Loss) after tax | D8: =+'P&L'!D33+'P&L'!D29 -> 124538032 | E8: =+'P&L'!E33+'P&L'!E29 -> 71647844
B9: Add: Provision for Income tax | D9: =+'P&L'!D27 -> 46429720 | E9: =+'P&L'!E27 -> 27635821
B10: Adjustment for:
B11: Depreciation and Amortization Expense | D11: =+'P&L'!D15 -> 1813010 | E11: =+'P&L'!E15 -> 1079988
B12: Provision for Gratuity | D12: 1204777 | E12: 0
B13: Prior Period Adjustment | D13: =+'Notes - '!D9:E9 -> -183832 | E13: 0
B14: Interest & Other Finance Charges | D14: =+'P&L'!D14 -> 2636496 | E14: =+'P&L'!E14 -> 2042977
B15: Interest Income | D15: =-'Notes-P&L'!C18 -> -299009 | E15: 0
B16: (Profit) / Loss on Sale / Write off Assets | D16: 0 | E16: 0
B17: Operating Profit before Working Capital Changes | D17: =SUM(D8:D16) -> 176139194 | E17: =SUM(E8:E16) -> 102406630
B18: Changes in Working Capital:
B19: (Increase) / Decrease in Trade Receivables | D19: =+BS!E35-BS!D35 -> -453850831 | E19: =+BS!G35-BS!E35 -> -169026309
B20: (Increase) / Decrease in Inventories | D20: =+BS!E34-BS!D34 -> 78688215 | E20: =+BS!G34-BS!E34 -> 140135028
B21: (Increase) / Decrease in Short term Loans & Advances | D21: =+BS!E37-BS!D37 -> -69566948 | E21: =+BS!G37-BS!E37 -> 7221232
B22: (Increase) / Decrease in Other Current Assets | D22: =+BS!E38-BS!D38 -> -10665746 | E22: =+BS!G38-BS!E38 -> 7887664
B23: Increase / (Decrease) in Trade Payables | D23: =+BS!D19-BS!E19 -> 84920623 | E23: =+BS!E19-BS!G19 -> 75763442
B24: Increase / (Decrease) in Short term Provisions | D24: =+BS!D21-BS!E21-CFS!D9-CFS!D28 -> -1935232 | E24: =+BS!E21-BS!G21-E9-E28 -> -2532838
B25: Increase / (Decrease) in Other Current Liabilities | D25: =+BS!D20-BS!E20 -> 61093313 | E25: =+BS!E20-BS!G20 -> -178214202
B26: Cash Generated from Operations | D26: =SUM(D17:D25) -> -135177412 | E26: =SUM(E17:E25) -> -16359353
B27: Add: Income-Tax Refunded | D27: 0 | E27: 0
B28: Less: Income Taxes Paid | D28: =-E9 -> -27635821 | E28: 0
B29: Net Cash Flow from Operating Activities (A) | D29: =SUM(D26:D28) -> -162813233 | E29: =SUM(E26:E28) -> -16359353
A31: B | B31: CASH FLOW FROM INVESTING ACTIVITIES:
B32: Purchase of Property, Plant and Equipment | D32: =+BS!E26+BS!E27-BS!D26-BS!D27-D11 -> -8976633 | E32: =+BS!G26+BS!G27-BS!E26-BS!E27-E11 -> -2560557
B33: Changes in Other Non Current Assets | D33: =+BS!E31-BS!D31 -> -37000000 | E33: =+BS!G31-BS!E31 -> -10000000
B34: Interest Received | D34: =-D15 -> 299009 | E34: =-E15 -> 0
B35: Net Cash Flow used in Investing Activities (B) | D35: =SUM(D32:D34) -> -45677624 | E35: =SUM(E32:E34) -> -12560557
A37: C | B37: CASH FLOW FROM FINANCING ACTIVITIES:
B38: Interest & Other Finance Charges on Loan Paid | D38: =-D14 -> -2636496 | E38: =-E14 -> -2042977
B39: Proceeds from Issue of Share Capital | D39: =+BS!D9-BS!E9+'Notes - '!D14:E14 -> 206515622 | E39: =+BS!E9-BS!G9+12533396 -> 13200066
B40: Changes in Other Long-term Liabilities | D40: 0 | E40: 0
B41: Changes in Long-Term Borrowings | D41: =+BS!D13-BS!E13 -> 157155 | E41: =+BS!E13-BS!G13 -> -984601
B42: Changes in Short-term Borrowings | D42: =+BS!D18-BS!E18 -> 21812328 | E42: =+BS!E18-BS!G18 -> 28423168
...

Sheet Note 4 - SOCES
A1: =+BS!A1 -> PROGEN RENEWABLES LIMITED
A2: Notes Forming Part of the Financial Statements for the year ended 31th March 2025
A4: Note: 1 Share Capital
A5: Particulars | D5: As at March 31, 2025 | F5: As at March 31, 2024 | H5: As at March 31, 2023
D6: Number | E6: Amount | F6: Number | G6: Amount | H6: Number | I6: Amount
A7: AUTHORISED
A8: Equity Shares par value of Rs.10 /- each | D8: 17000000 | E8: 170000000 | F8: 170000 | G8: 1700000 | H8: 100000 | I8: =+H8*10 -> 1000000
D9: =SUM(D7:D8) -> 17000000 | E9: =SUM(E7:E8) -> 170000000 | F9: =SUM(F7:F8) -> 170000 | G9: =SUM(G7:G8) -> 1700000 | H9: =SUM(H7:H8) -> 100000 | I9: =SUM(I7:I8) -> 1000000
A10: ISSUED, SUBSCRIBED AND FULLY PAID UP
A11: Equity Shares par value of Rs.10/- each | D11: 187224 | E11: 1872240 | F11: 166667 | G11: 1666670 | H11: 100000 | I11: =+H11*10 -> 1000000
D12: =SUM(D10:D11) -> 187224 | E12: =SUM(E10:E11) -> 1872240 | F12: =SUM(F10:F11) -> 166667 | G12: =SUM(G10:G11) -> 1666670 | H12: =SUM(H10:H11) -> 100000 | I12: =SUM(I10:I11) -> 1000000
A14: Note: 1.1 Term / Rights attached to equity shares
A15: The Company has only one class of equity shares having a par of value of Rs.10/- per share. Each holder of equity share is entitled to one vote per share. The divident proposed by the board of directors is subject to the approval of the shareholders in the ensuring Annual General Meeting, except in case of interim divident. In the event of liquidation of the company, The holders of equity shares will be entitled to receive remaining assets of the company, after distribution of all preferential amounts. The distribution will be in proportion to the no. of equity shares held by the shareholder.
A17: Note: 1.2 Reconciliation of equity shares outstanding at the beginning and at the end of the year:
A18: Particulars | D18: As at 31st March, 2025 | F18: As at 31st March, 2024 | H18: As at 31st March, 2023
A19: Equity Shares | D19: No. of shares | E19: Amount | F19: No. of shares | G19: Amount | H19: No of Shares | I19: Amount
A20: At the beginning of the year | D20: =+F22 -> 166667 | E20: =+G22 -> 1666670 | F20: 100000 | G20: 1000000 | H20: 100000 | I20: =+H20*10 -> 1000000
A21: Add: Shares issued during the year | D21: 20557 | E21: =+D21*10 -> 205570 | F21: 66667 | G21: 666670 | H21: 0 | I21: 0
A22: Outstanding at the end of the year | D22: =SUM(D20:D21) -> 187224 | E22: =SUM(E20:E21) -> 1872240 | F22: =SUM(F20:F21) -> 166667 | G22: =SUM(G20:G21) -> 1666670 | H22: =SUM(H20:H21) -> 100000 | I22: =SUM(I20:I21) -> 1000000
A24: Note: 1.3 Details of Shareholders holding more than 5% of the Equity Share Capital of the Company:
A25: Particulars | D25: As at 31st March, 2025 | F25: As at March 31, 2024 | H25: As at March 31, 2023
A26: Equity Shares | D26: Numbers | E26: % of Holding | F26: Numbers | G26: % of Holding | H26: Numbers | I26: % of Holding
A27: Mr. Alfred Vinod Antony | D27: 50000 | E27: =+D27/D22 -> 0.26705978 | F27: 50000 | G27: =+F27/F22 -> 0.2999994 | H27: 50000 | I27: =+H27/H22 -> 0.5
A28: Mrs. Veena Jose | D28: 50000 | E28: =+D28/D22 -> 0.26705978 | F28: 50000 | G28: =+F28/F22 -> 0.2999994 | H28: 50000 | I28: =+H28/H22 -> 0.5
A29: Mr. Arvind Jain | D29: 44198 | E29: =+D29/D22 -> 0.23607016 | F29: 66667 | G29: =+F29/F22 -> 0.4000012 | H29: 0 | I29: 0
A31: Note: 1.4 Details of Promoter Shareholding :-
A32: The details of the shares held by promoters as at March 31, 2025 are as follows :
A33: S.No | B33: Name of the Promotor (P) / Promotor Group (PG) | C33: As on 31-Mar-2025 | E33: As on 31-Mar-2024 | G33: % Change during the year | H33: As on 31-March 2023
C34: No of Shares | D34: % of Total shares | E34: No of Shares | F34: % of Total shares | H34: No of Shares | I34: % of Total Shares
A35: 1 | B35: Mr. Alfred Vinod Antony | C35: 50000 | D35: =+C35/D22 -> 0.26705978 | E35: 50000 | F35: =+E35/F22 -> 0.2999994 | G35: =+D35-F35 -> -0.032939621 | H35: 50000 | I35: =+H35/H22 -> 0.5
A36: 2 | B36: Mrs. Veena Jose | C36: 50000 | D36: =+C36/D22 -> 0.26705978 | E36: 50000 | F36: =+E36/F22 -> 0.2999994 | G36: =+D36-F36 -> -0.032939621 | H36: 50000 | I36: =+H36/H22 -> 0.5
A37: 3 | B37: Mr. Arvind Jain | C37: 44198 | D37: =+C37/D22 -> 0.23607016 | E37: 66667 | F37: =+E37/F22 -> 0.4000012 | G37: =+D37-F37 -> -0.16393104
C38: =SUM(C35:C37) -> 144198 | D38: =SUM(D35:D37) -> 0.77018972 | E38: =SUM(E35:E37) -> 166667 | F38: =SUM(F35:F37) -> 1 | G38: =SUM(G35:G37) -> -0.22981028

Sheet Notes - 
A1: =+BS!A1 -> PROGEN RENEWABLES LIMITED
A2: Notes Forming Part of the Financial Statements for the year ended 31th March 2025
A4: Note: 2 Reserve & Serplus
A5: S.No | B5: Particulars | D5: =+'Note 4 - SOCES'!D25 -> As at 31st March, 2025 | F5: As at 31st March, 2024 | H5: As at 31st March, 2023
A6: 1 | B6: Surplus/ (Deficit) in the statement of P&L
B7: Balance at the beginning of the year | D7: =+F10 -> 106082897 | F7: 34498048 | H7: 19588654
B8: Add / (Less) : Profit/ (loss) for the year | D8: =+'P&L'!D33 -> 126295478 | F8: =+'P&L'!E33 -> 71584849 | H8: =+'P&L'!F33 -> 14909394
B9: Add/(Less): Prior Period Adjustment | D9: -183832 | F9: 0 | H9: 0
B10: Balance at the end of the year | D10: =SUM(D7:E9) -> 232194543 | F10: =SUM(F7:G9) -> 106082897 | H10: =SUM(H6:H8) -> 34498048
A12: 2 | B12: Securities Premium :-
B13: Balance at the Beginning of the year | D13: =+F15 -> 12533396 | F13: =+H15 -> 0 | H13: 0
B14: Add: Additions during the year | D14: 206310052 | F14: 12533396 | H14: 0
B15: Balance at the end of the year | D15: =SUM(D11:E14) -> 218843448 | F15: =SUM(F11:G14) -> 12533396 | H15: =SUM(H11:H14) -> 0
B17: Total | D17: =+D10+D15 -> 451037991 | F17: =+F10+F15 -> 118616293 | H17: =+H10+H15 -> 34498048
A19: Note: 3 Long-term Borrowing
A20: S.No | B20: Particulars | D20: As at 31st March, 2025 | F20: As at 31st March, 2024 | H20: As at 31st March, 2023
A21: 1 | B21: Vehicle Loans from Bank - Secured | D21: 3535457 | F21: 3036391 | H21: 3989485
B22: Less: Current Maturities of Long-term Borrowings | D22: -1326512 | F22: -984601 | H22: -953094
B24: Total | D24: =+D21+D22 -> 2208945 | F24: =+F21+F22 -> 2051790 | H24: =+H21+H22 -> 3036391
A26: Note : 3.1 Details of Long term Borrowings
A27: S.No | B27: Particulars of Loan and Term & Conditions
A28: 1 | B28: A. Nature of Loan : Vehicle Loan - ICICI Bank A/c LACBT00044569222. B. Term & Conditions : A loan of ₹18,00,000 was sanctioned at an interest rate of 7.5% per annum, repayable in 60 equal monthly installments of ₹36,009 each. The loan was disbursed on 10th November 2021 and will mature on 10th October 2026. C. Nature of Security : Toyota Innova Crysta - Car
A29: 2 | B29: A. Nature of Loan : Vehicle Loan - ICICI Bank A/c LACBT00050418274. B. Term & Conditions : A loan of ₹ 8,00,000 was sanctioned at an interest rate of 9.40% per annum, repayable in 60 equal monthly installments of ₹ 16,763 each. The loan was disbursed on 10th November 2024 and will mature on 10th October 2029. C. Nature of Security : Mahindra XUV3XO AX5 PM MT BS6 2
A30: 3 | B30: A. Nature of Loan : Vehicle Loan - ICICI Bank A/c LACBT00050283942 B. Term & Conditions : A loan of ₹ 8,00,000 was sanctioned at an interest rate of 9.55% per annum, repayable in 60 equal monthly installments of ₹ 16,844 each. The loan was disbursed on 10th October 2024 and will mature on 10th September 2029. C. Nature of Security : Maruti Ertiga Smart Hybris VXI 1.5L 5MT-ERR4HV1
A33: PROGEN RENEWABLES LIMITED
A34: Notes Forming Part of the Financial Statements for the year ended 31th March 2025
A36: 4 | B36: A. Nature of Loan : Vehicle Loan - Induslnd Bank A/c TKG08474C B. Term & Conditions : A loan of ₹ 7,00,000 was sanctioned at an interest rate of 8.14% per annum, repayable in 60 (One Month Moratorium) equal monthly installments of ₹ 14,400 each. The loan was disbursed on 07th November 2021 and will mature on 07th September 2026. C. Nature of Security : Maruti Ertiga Smart Hybrid VXI BS VI
A37: 5 | B37: A. Nature of Loan : Vehicle Loan - Induslnd Bank A/c TKG08474C B. Term & Conditions : A loan of ₹ 23,08,000 was sanctioned at an interest rate of 8.50% per annum, repayable in 60 (One Month Moratorium) equal monthly installments of ₹ 47,999 each. The loan was disbursed on 15th August 2022 and will mature on 15th June 2027. C. Nature of Security : Toyota Innova Crysta 2.4 ZX 7S MT BS VI
A39: Note: 4 Deferred tax Liabilities (Net)
A40: S.No | B40: Particulars | D40: As at 31st March, 2025 | F40: As at 31st March, 2024 | H40: As at 31st March, 2023
A41: 1 | B41: Opening Balance DTL / (DTA) | D41: =+F44 -> 225648 | F41: =+H44 -> 162653 | H41: 59908
B42: Add / (Less) : Current year (DTA) / DTL | D42: -1757446 | F42: =+'P&L'!E29 -> 62995 | H42: =+'P&L'!F29 -> 102745
B44: Closing Balance | D44: =SUM(D41:E43) -> -1531798 | F44: =SUM(F41:G43) -> 225648 | H44: =SUM(H41:H43) -> 162653
A46: Note: 5 Long term Provisions
A47: S.No | B47: Particulars | D47: As at 3st March, 2025 | F47: As at 31st March, 2024
A48: 1 | B48: Provision for Gratuity | D48: =+'Notes-P&L'!C56 -> 1204777 | F48: 0
B50: Total | D50: =SUM(D48:E49) -> 1204777 | F50: =SUM(F48:G49) -> 0
A52: Note: 6 Short-term Borrowing
A53: S.No | B53: Particulars | D53: As at 31st March, 2025 | F53: As at 31st March, 2024 | H53: As at 31st March, 2023
A54: 1 | B54: Loan Repayable on demand from bank - Secured :-
...

Sheet Notes
A1: =+BS!A1 -> PROGEN RENEWABLES LIMITED
A2: =+'Note 4 - SOCES'!A2:G2 -> Notes Forming Part of the Financial Statements for the year ended 31th March 2025
A4: Note : 10 Property, Plant and Equipments
A6: S.No | B6: Name of the Assets | C6: Useful Life | D6: Gross Block | H6: Accumulated Depreciation / Amortization | L6: Net Block
D7: Balance as at 31st March 2024 | E7: Additions during the year | F7: Deletions during the year | G7: Balance as at 31st March 2025 | H7: Balance as at 31st March 2024 | I7: Provided during the year | J7: Add / Less from Retained Earings | K7: Balance as at 31st March 2025 | L7: Balance as at 31st March 2024 | M7: Balance as at 31st March 2025 | N7: Balance as at 31st March 2023
B8: A. Tangible Assets
B9: Own Assets :
A10: 1 | B10: Land | D10: 959887 | E10: 0 | F10: 0 | G10: =+D10+E10-F10 -> 959887 | H10: 0 | I10: 0 | J10: 0 | K10: =+H10+I10+J10 -> 0 | L10: =+D10-H10 -> 959887 | M10: =+G10-K10 -> 959887 | N10: 959887
A11: 2 | B11: Laptop & Computers | C11: 3 | D11: 629255 | E11: 711249 | F11: 0 | G11: =+D11+E11-F11 -> 1340504 | H11: 230817 | I11: 189046 | J11: 192078 | K11: =+H11+I11+J11 -> 611941 | L11: =+D11-H11 -> 398438 | M11: =+G11-K11 -> 728563 | N11: 330329
A12: 3 | B12: Plant & Machinery | C12: 15 | D12: 109251 | E12: 483449 | F12: 0 | G12: =+D12+E12-F12 -> 592700 | H12: 23131 | I12: 15893 | J12: 9845 | K12: =+H12+I12+J12 -> 48869 | L12: =+D12-H12 -> 86120 | M12: =+G12-K12 -> 543831 | N12: 51584
A13: 4 | B13: Vehicle - Two Wheeler | C13: 10 | D13: 535292 | E13: 220292 | F13: 0 | G13: =+D13+E13-F13 -> 755584 | H13: 123061 | I13: 64841 | J13: 9241 | K13: =+H13+I13+J13 -> 197143 | L13: =+D13-H13 -> 412231 | M13: =+G13-K13 -> 558441 | N13: 454059
A14: 5 | B14: Vehicle - Car | C14: 8 | D14: 7278480 | E14: 4302998 | F14: 0 | G14: =+D14+E14-F14 -> 11581478 | H14: 1588384 | I14: 1086269 | J14: 2620 | K14: =+H14+I14+J14 -> 2677273 | L14: =+D14-H14 -> 5690096 | M14: =+G14-K14 -> 8904205 | N14: 5348460
A15: 6 | B15: Electrical Fittings | C15: 10 | D15: 276264 | E15: 1225832 | F15: 0 | G15: =+D15+E15-F15 -> 1502096 | H15: 60059 | I15: 58294 | J15: 111 | K15: =+H15+I15+J15 -> 118464 | L15: =+D15-H15 -> 216205 | M15: =+G15-K15 -> 1383632 | N15: 142140
A16: 7 | B16: Office Equipments | C16: 5 | D16: 278735 | E16: 388805 | F16: 0 | G16: =+D16+E16-F16 -> 667540 | H16: 16058 | I16: 96588 | J16: 159 | K16: =+H16+I16+J16 -> 112805 | L16: =+D16-H16 -> 262677 | M16: =+G16-K16 -> 554735 | N16: 21495
A17: 8 | B17: Furniture & Fittings | C17: 10 | D17: 668605 | E17: 1784361 | F17: 0 | G17: =+D17+E17-F17 -> 2452966 | H17: 14901 | I17: 110060 | J17: 175 | K17: =+H17+I17+J17 -> 125136 | L17: =+D17-H17 -> 653704 | M17: =+G17-K17 -> 2327830 | N17: 20443
A18: 9 | B18: Tools & Equipments | C18: 5 | D18: 588301 | E18: 43479 | F18: 0 | G18: =+D18+E18-F18 -> 631780 | H18: 253861 | I18: 113682 | J18: 448 | K18: =+H18+I18+J18 -> 367991 | L18: =+D18-H18 -> 334440 | M18: =+G18-K18 -> 263789 | N18: 380738
B19: Total (A) | D19: =SUM(D10:D18) -> 11324070 | E19: =SUM(E10:E18) -> 9160465 | F19: =SUM(F10:F18) -> 0 | G19: =SUM(G10:G18) -> 20484535 | H19: =SUM(H10:H18) -> 2310272 | I19: =SUM(I10:I18) -> 1734673 | J19: =SUM(J10:J18) -> 214677 | K19: =SUM(K10:K18) -> 4259622 | ... N19: =SUM(N10:N18) -> 7709135
B20: B. Intangible Assets
A21: 1 | B21: Software | C21: 3 | D21: 595280 | E21: 0 | F21: 0 | G21: =+D21+E21-F21 -> 595280 | H21: =+[1]FA!$I$17 -> 419374 | I21: 78337 | J21: -30845 | K21: =+H21+I21+J21 -> 466866 | L21: =+D21-H21 -> 175906 | M21: =+G21-K21 -> 128414 | N21: 0
B22: Total (B) | D22: =SUM(D21:D21) -> 595280 | E22: =SUM(E21:E21) -> 0 | F22: =SUM(F21:F21) -> 0 | G22: =SUM(G21:G21) -> 595280 | H22: =SUM(H21:H21) -> 419374 | I22: =SUM(I21:I21) -> 78337 | J22: =SUM(J21:J21) -> -30845 | K22: =SUM(K21:K21) -> 466866 | ... M22: =SUM(M21:M21) -> 128414 | N22: =SUM(N21) -> 0
B23: C. Capital Work-in-Progress
D24: 0 | E24: 0 | F24: 0 | G24: =+D24+E24-F24 -> 0 | H24: 0 | I24: 0 | J24: 0 | K24: =+H24+I24 -> 0 | L24: =+D24-H24 -> 0 | M24: =+G24-K24 -> 0 | N24: 0
B25: Total ( C) | D25: =SUM(D24:D24) -> 0 | E25: =SUM(E24:E24) -> 0 | F25: =SUM(F24:F24) -> 0 | G25: =SUM(G24:G24) -> 0 | H25: =SUM(H24:H24) -> 0 | I25: =SUM(I24:I24) -> 0 | J25: =SUM(J24:J24) -> 0 | K25: =SUM(K24:K24) -> 0 | ... M25: =SUM(M24:M24) -> 0 | N25: =SUM(N24) -> 0
B27: Total(A+B+C) | D27: =+D19+D22+D25 -> 11919350 | E27: =+E19+E22+E25 -> 9160465 | F27: =+F19+F22+F25 -> 0 | G27: =+G19+G22+G25 -> 21079815 | H27: =+H19+H22+H25 -> 2729646 | I27: =+I19+I22+I25 -> 1813010 | J27: =+J19+J22+J25 -> 183832 | K27: =+K19+K22+K25 -> 4726488 | ... N27: =+N19+N22+N25 -> 7709135

Sheet Notes -
A1: =+'Notes - '!A1:G1 -> PROGEN RENEWABLES LIMITED
A2: =+'Notes - '!A2:G2 -> Notes Forming Part of the Financial Statements for the year ended 31th March 2025
A4: Note : 11 Long term loans & Advances
A5: S.No | B5: Particulars | F5: As at 31st March, 2025 | H5: As at 31st March, 2024 | J5: As at 31st March, 2023
A6: 1 | B6: Other Loans and Advances :-
B7: - Arun Rosario | F7: 0 | H7: 740000 | J7: 740000
B8: - Rent Advance | F8: 109000 | H8: 0 | J8: 0
B10: Total | F10: =SUM(F6:G9) -> 109000 | H10: =SUM(H6:I9) -> 740000 | J10: =SUM(J6:J9) -> 740000
A12: Note: 12 Other Non-Current Assets
A13: S.No | B13: Particulars | F13: As at 31st March, 2025 | H13: As at 31st March, 2024 | J13: As at 31st March 2023
A14: 1 | B14: Security Deposits :-
B15: - EB Load Purchases (Refundable) | F15: 21500000 | H15: 10000000 | J15: 0
A16: 2 | B16: Fixed Deposits | F16: 25500000 | H16: 0
B18: Total | F18: =SUM(F14:G17) -> 47000000 | H18: =SUM(H14:I17) -> 10000000 | J18: =SUM(J14:J17) -> 0
A20: Note : 13 Inventories
A21: S.No | B21: Particulars | F21: As at 31st March, 2025 | H21: As at 31st March, 2024 | J21: As at 31st March 2023
A22: 1 | B22: Raw Materials | F22: =+'Notes-P&L'!C40 -> 1141959 | H22: =+'Notes-P&L'!D40 -> 112014200 | J22: =+'Notes-P&L'!E40 -> 257149228
A23: 2 | B23: Project Land | F23: =+'Notes-P&L'!C41 -> 37184026 | H23: =+'Notes-P&L'!D41 -> 5000000 | J23: =+'Notes-P&L'!E41 -> 0
B25: Total | F25: =SUM(F22:G24) -> 38325985 | H25: =SUM(H22:I24) -> 117014200 | J25: =SUM(J22:J24) -> 257149228
A27: Note : 14 Trade receivables
A28: S.No | B28: Particulars | F28: As at 31st March, 2025 | H28: As at 31st March, 2024 | J28: As at 31st March 2023
A29: 1 | B29: Secured, Considered goods | F29: =+'SC & SD'!R68 -> 700374795 | H29: =+'SC & SD'!S68 -> 246523964 | J29: 77497655
A30: 2 | B30: Un-secured, Considered goods | F30: 0 | H30: 0 | J30: 0
A31: 3 | B31: Doubtful | F31: 0 | H31: 0 | J31: 0
B32: Sub-Total | F32: =SUM(F29:G31) -> 700374795 | H32: =SUM(H29:I31) -> 246523964 | J32: =SUM(J29:J31) -> 77497655
B33: Less: Provision for doubtful debts | F33: 0 | H33: 0 | J33: 0
B35: Total | F35: =SUM(F32:G34) -> 700374795 | H35: =SUM(H32:I34) -> 246523964 | J35: =SUM(J32:J34) -> 77497655
A46: PROGEN RENEWABLES LIMITED
A47: Notes Forming Part of the Financial Statements for the year ended 31th March 2025
A49: 14.1. AGEING ANALYSIS OF TRADE RECEIVABLES :
A50: 14.1.1.Trade Receivable Ageing Schedule as at March, 2025
A51: Particulars | D51: Outstanding for following periods from due date of transaction | I51: Total
D52: < 6 Months | E52: 6 Months to 1 year | F52: 1 - 2 Years | G52: 2 - 3 Years | H52: > 3 years
A53: (i) Undisputed Trade Receivables - Considered Goods | D53: 615688092 | E53: 190992 | F53: 84495711 | G53: 0 | H53: 0 | I53: =SUM(D53:H53) -> 700374795
A54: (ii) Undisputed Trade Receivables - Credit impaired | D54: 0 | E54: 0 | F54: 0 | G54: 0 | H54: 0 | I54: =SUM(D54:H54) -> 0
A55: (iii) Disputed Trade Receivables - Considered goods | D55: 0 | E55: 0 | F55: 0 | G55: 0 | H55: 0 | I55: =SUM(D55:H55) -> 0
A56: (iv) Disputed Trade Receivables - Credit Impaired | D56: 0 | E56: 0 | F56: 0 | G56: 0 | H56: 0 | I56: =SUM(D56:H56) -> 0
A57: Total | D57: =SUM(D53:D56) -> 615688092 | E57: =SUM(E53:E56) -> 190992 | F57: =SUM(F53:F56) -> 84495711 | G57: =SUM(G53:G56) -> 0 | H57: =SUM(H53:H56) -> 0 | I57: =SUM(I53:I56) -> 700374795
A59: 14.1.2.Trade Receivable Ageing Schedule as at March, 2024
A60: Particulars | D60: Outstanding for following periods from due date of transaction | I60: Total
...

Sheet Notes-P&L
A1: =+'Note 4 - SOCES'!A1:G1 -> PROGEN RENEWABLES LIMITED
A2: =+'Note 4 - SOCES'!A2:G2 -> Notes Forming Part of the Financial Statements for the year ended 31th March 2025
A4: Note : 18 Revenue from Operations
A5: S.No | B5: Particulars | C5: For the year ended March 31, 2025 | D5: For the year ended March 31, 2024 | E5: For the year ended March 31, 2023
A6: 1 | B6: Sale of Solar Power Plant | C6: =840845908+488641923 -> 1329487831 | D6: =742589031+371250191 -> 1113839222 | E6: =336702091+227193833 -> 563895924
A7: 3 | B7: Project Land Sale | C7: =12034300+2264170 -> 14298470 | D7: 0 | E7: 19750
A8: 4 | B8: Other operating revenues | C8: =2460000+163600+2360 -> 2625960 | D8: =2418750+33100 -> 2451850 | E8: =1000000+79000+63170 -> 1142170
B9: Total Revenue | C9: =SUM(C6:C8) -> 1346412261 | D9: =SUM(D6:D8) -> 1116291072 | E9: =SUM(E6:E8) -> 565057844
B10: Geographical Markets
A11: 1 | B11: In India | C11: =+C9 -> 1346412261 | D11: =+D9 -> 1116291072 | E11: =+E9 -> 565057844
A12: 2 | B12: Outside India | C12: 0 | D12: 0 | E12: 0
B13: Total Revenue from Operations | C13: =SUM(C11:C12) -> 1346412261 | D13: =SUM(D11:D12) -> 1116291072 | E13: =SUM(E11:E12) -> 565057844
A15: Note: 19 Other Income
A16: S.No | B16: Particulars | C16: For the year ended March 31, 2025 | D16: For the year ended March 31, 2024 | E16: For the year ended March 31, 2023
A17: 1 | B17: Commission Income | C17: 501000 | D17: 321740 | E17: 0
A18: 2 | B18: Interest on Fixed Deposit | C18: =299009 -> 299009 | D18: 0 | E18: 0
A19: 3 | B19: Other Non-operating Income
B20: - Discount Received | C20: 10943 | D20: 16534 | E20: 0
B21: - Insurance Refund | C21: 65556 | D21: 0 | E21: 0
B23: Total | C23: =SUM(C17:C22) -> 876508 | D23: =SUM(D17:D22) -> 338274 | E23: =SUM(E17:E22) -> 0
A25: Note: 20 Purchase of Stock in Trade
A26: S.No | B26: Particulars | C26: For the year ended March 31, 2025 | D26: For the year ended March 31, 2024 | E26: For the year ended March 31, 2023
A27: 1 | B27: Raw Material Purchase
B28: - Domestic Purchase | C28: =248559362+29932624+2249286+167581732+145854519+2275853 -> 596453376 | D28: 575029597 | E28: 321635156
B29: - Import Purchase | C29: 42680536 | D29: 66364367 | E29: 0
A30: 2 | B30: Project Land Purchase | C30: 74138272 | D30: 49138475 | E30: 0
B32: Cost of Material Consumed | C32: =SUM(C27:C31) -> 713272184 | D32: =SUM(D27:D31) -> 690532439 | E32: =SUM(E27:E31) -> 321635156
A34: Note: 21 Changes in inventories of Work-in Progross, Finished Goods
A35: S.No | B35: Particulars | C35: =+C5 -> For the year ended March 31, 2025 | D35: For the year ended March 31, 2024 | E35: =+E26 -> For the year ended March 31, 2023
B36: Opening stock : -
B37: - Raw Materials | C37: =+D40 -> 112014200 | D37: =+E40 -> 257149228 | E37: 417707050
B38: - Land | C38: =+D41 -> 5000000 | D38: =+E41 -> 0 | E38: 0
B39: Closing stock : -
B40: - Raw Materials | C40: 1141959 | D40: 112014200 | E40: 257149228
B41: - Land | C41: 37184026 | D41: 5000000 | E41: 0
B43: Changes in Inventory | C43: =+C37+C38-C40-C41 -> 78688215 | D43: =+D37+D38-D40-D41 -> 140135028 | E43: =+E37+E38-E40-E41 -> 160557822
A45: PROGEN RENEWABLES LIMITED
A46: Notes Forming Part of the Financial Statements for the year ended 31th March 2025
A48: Note: 22 Employee Benefits Expenses
A49: S.No | B49: Particulars | C49: =+C5 -> For the year ended March 31, 2025 | D49: For the year ended March 31, 2024 | E49: =+E35 -> For the year ended March 31, 2023
...

Sheet SAP
B1: 26 | C1: CORPORATE INFORMATION: -
C2: M/s. PROGEN RENEWABLES LIMITED [CIN: U31909TZ2017PLC029803] is a Public Limited Company incorporated in India on December 21, 2017 under the Provisions of the Companies Act, 2013 having its Registered Office at 87 A, First Floor, Sathy Road, Muniappan Koil Street, Ganapathy, Coimbatore, Tamil Nadu - 641 006.
C3: The company is in the business of engineering, procurement, and construction (EPC) of power projects, as well as operation and maintenace services. The company currently has multiple solar power projects located at various locations with a combined installed and commissioned capacity of more than 15 - 20 MW as at 31st March 2025.
B5: 27 | C5: GENERAL INFORMATION: -
B6: 27.1 | C6: BASIS OF PREPARATION AND MEASUREMENT: -
C7: The Financial Statements of the Company have been prepared under the historical cost convention on an accrual basis.
C8: The Financial Statements have been prepared in Accordance with the Generally Accepted Accounting Principles in India (Indian GAAP) including Accounting Standards notified under Section 133 of Companies Act, 2013 read with Rule 7 of the Companies (Accounts) Rules, 2014 and the relevant provisions of the Companies Act, 2013.
C9: The Company follows Mercantile System of Accounting and recognizes Income & Expenditure on an accrual basis except in case of significant uncertainties.
C10: The Company's financial statements are presented in Indian Rupees, which is also its functional currency and all values are rounded to nearest thousands, except when otherwise indicated.
B12: 27.2 | C12: USE OF ESTIMATES: -
C13: The Preparation of financial statements in conformity with Indian GAAP requires the management to make judgements, estimates and assumptions that affect the applications of accounting policies and the reported amounts of assets, liabilities, income and expenses and disclosure of contingent liabilities, at the end of the reporting period.
C14: Actual results may differ from these estimates. Estimates and underlying assumptions are reviewed at each balance sheet date, Revisions to accounting estimates are recognised in the period in which the estimate is revised and future periods.
B16: 27.3 | C16: OPERATING CYCLE: -
C17: All assets and liabilities have been classified as current or non-current as per the Company's normal operating cycle. Based on the nature of services and the time between the acquisition of assets for providing of services and their realisation in cash and cash equivalents, the Company has ascertained its operating cycle as 12 months.
B19: 27.4 | C19: CLASSIFICATION OF ASSETS & LIABILITIES AS CURRENT & NON-CURRENT: -
C20: 27.4.1. An entity shall Classify an asset as current when -
C21: a. It is expected to be realised in, or is intended for sale or consumption in, the company's normal operating cycle;
C22: b. It is held primarily for the purpose of being traded;
C23: c. It is expected to be realised within 12 Months after the reporting date or
C24: d. It is cash or cash equivalent unless it is restricted from being exchanged or used to settle a liability for at least 12 Months after the reporting date.
C25: All other assets shall be classified as non-current.
C27: 27.4.2. An entity shall classify liabilities as current when -
C28: a. It is expected to be settled in the company's normal operating cycle;
C29: b. It is held primarily for the purpose of being trading;
C30: c. It is due to be settled within 12 Months after the reporting date; or
C31: d. The company does not have an unconditional right to defer settlement of the liability for at least 12 Months after the reporting date. Terms of a liability that could, at the option of the counterparty, result in its settlement by the issue of equity instruments to not affact its classification.
C32: All other liabilities shall be classified as non-current.
B34: 28 | C34: SIGNIFICANT ACCOUNTING POLICIES: -
B35: 28.1 | C35: FIXED ASSETS: -
C36: 28.1.1. Tangible Assets:
C37: PPE is recognized when it is probable that future economic benefits associated with the item will flow to the company and the cost of the item can be measured reliably. PPE is stated at original cost net of tax / duty credit availed, if any, less accumulated depreciation and cumulative impairment.
C38: Cost of an item of PPE includes Purchase cost and any cost directly attributable to bringing the assets to the “location and condition” necessary for it to be capable of operating in the manner intended by management. The Gain or Loss arising on disposal of an assets is determined as the difference between the sale of goods and the carrying amount of the asset and is recognised in the statement of profit and loss.
C39: Depreciation is calculated on the cost of Fixed assets less their estimated residual values using the straight-line method over the estimated useful lives and is generally recognised in the statement of Profit and Loss Account. Freehold land is not depreciated
C40: Depreciation on tangible assets is provided (on the SLM basis) over the useful lives estimated as per Schedule II of Companies Act, 2013. Depreciation for assets purchased / sold during a period is proportionately charged.
C42: 28.1.2. Intangible Assets:
C43: Intangible assets are stated at original cost net of tax / duty credit availed, if any, less accumulated depreciation and cumulative impairment. Intangible assets are recognized when it is probable that future economic benefits that are attributable to the assets will flow to the company and the cost of the item can be measured reliably.
C44: Intangible assets are amortized on straight line basis over the estimated useful life which is the period of three years
C46: 28.1.3. Capital Work-in-Progress:
C47: PPE not ready for the intended use on the date of balance sheet are disclosed as ‘Capital Work-in Progress’
B49: 28.2 | C49: IMPAIRMENT OF ASSETS: -
...

Sheet SAP 2
A1: DISCLOSURE REQUIRMENTS :-
A2: 29. Disclosure pursuant to AS 15 " Employee Benefit Expenses"
A3: 29.1. Contribution to Defined Contribution Plan :
A4: The Company has defined contribution plan. Contributions are made to provident fund in India for employees at the rate of 12% of basic salary as per regulations. The contributions are made to registered provident fund administrated by the government. Contribution to Employer State Insurance is 3.25% of the wages payable to the employees The obligation of the company is limited to the amount contributed and it has no further contratual nor any constructive obligation. The expenses recognised during the year towards defined contribution plan is as under ;
A6: Particulars | F6: For the year ended March 31, 2025 | H6: For the year ended March 31, 2024
A7: Contribution to Employees State Insurance | F7: 58173 | H7: 38317
A8: Contribution to Employees Provident Fund | F8: 56569 | H8: 421752
A9: Expenses recognised during the year | F9: =SUM(F7:G8) -> 114742 | H9: =SUM(H7:I8) -> 460069
A11: 29.2 Contribution of Defined Benefits Plan :
A12: The Company has a defined benefit plan for gratuity in accordance with the provisions of the Payment of Gratuity Act, 1972. The liability for gratuity has been determined based on actuarial valuation and recognized in the financial statements.
A13: During the year, the Company has recognized gratuity expense of ₹1,204.78 thousands in the Statement of Profit and Loss. The same amount has been provided as a liability under “Long term Provision” in the Balance Sheet.
A15: 30 Disclosure pursuant to AS 18 " Related Party Disclosures"
A16: 30.1 List of Related Parties & Their Relationship :
A17: 1 | B17: Key Management Personnel :-
B18: - Mr. Alfred Vinod Antony - Managing Director
B19: - Mr. Arvind Jain - Whole time Director
B20: - Mrs. Veena Jose - Director & CFO
B21: - Mrs. Migael Anitha Christina - Company Secretary
A23: 2 | B23: Directors or his Relatives
B24: - Mr. Karthik Veluchamy Kottur - Independent Director
B25: - Mr. Shyam Sundar Venkatraman - Independent Director
B26: - Mr. Innocent Judejoseph Antonyjoseph - Independent Director
A28: 3 | B28: Private Companies in which a Director or his Relative is a Member or Director :-
B29: - M/s. Ashirvad Green Energy Private Limited
B30: - M/s. Udhayalakshmi Properties Limited
B31: - M/s. Maanvi Solar Private Limited
A33: 4 | B33: Firm or LLP in which a partner or his Relative is a Member or Director :-
B34: - M/s. Krynn Jewels and Diamonds LLP
A36: 5 | B36: Enterprises in which a KMP or his Relative have significant influence :-
B37: - Progen Energy Solutions
B38: - Rayaansh Arts and Jewels
B39: - Rayaansh Solar
A41: Note: 30.2 Transaction with Related Parties :-
A43: S.No | B43: Name of the Related Parties & their transactions | F43: For the year ended March 31, 2025 | H43: For the year ended March 31, 2024
A44: 1 | B44: Director Remuneration
B45: - Mr. Alfred Vinod Antony - Managing Director | F45: 3500000 | H45: 0
B46: - Mr. Arvind Jain - Whole time Director | F46: 3500000 | H46: 0
B47: - Mrs. Veena Jose - Director & CFO | F47: 350000 | H47: 0
A48: 2 | B48: Salary Paid
B49: - Mrs. Migael Anitha Christina - CS | F49: 216666 | H49: 0
...

Sheet Ratio
A1: =+BS!A1 -> PROGEN RENEWABLES LIMITED
A2: =+BS!A2 -> 87 A, First Floor, Sathy Road, Muniappan Koil Street, Ganapathy, Coimbatore,Tamil Nadu - 641 006.
A3: =+BS!A3 -> CIN : U31909TZ2017PLC029803
A5: Statement of Changes in Significant Accounting Ratio's :-
A7: S.No | B7: Particulars | C7: Numerator | D7: Denominator | E7: 31st March, 2025 | F7: 31st March, 2024 | G7: Changes In Ratio's | H7: Reason for change in ratio by more than 25%
A8: 1 | B8: Current Ratio | C8: Current Assets | D8: Current Liabilities | E8: =+'Ratio Working'!C5/'Ratio Working'!C6 -> 1.7370521 | F8: =+'Ratio Working'!D5/'Ratio Working'!D6 -> 1.2964027 | G8: =+K8 -> 0.33990161 | H8: Due to increase in Current Assets | J8: =+E8-F8 -> 0.44064937 | K8: =+J8/F8 -> 0.33990161
A9: 2 | B9: Debt-Equity Ratio | C9: Total Debt | D9: Shareholder's Equity | E9: =+'Ratio Working'!C7/'Ratio Working'!C8 -> 0.13815659 | F9: =+'Ratio Working'!D7/'Ratio Working'!D8 -> 0.33756278 | G9: =+K9 -> -0.59072326 | H9: Due to increase in Share holders Equity as compared to Borrowings | J9: =+E9-F9 -> -0.19940618 | K9: =+J9/F9 -> -0.59072326
A10: 3 | B10: Debt Service Coverage Ratio | C10: Earnings Available for Debt Service | D10: Debt Service | E10: =+'Ratio Working'!C9/'Ratio Working'!C10 -> 33.70202 | F10: =+'Ratio Working'!D9/'Ratio Working'!D10 -> 40.069212 | G10: =+K10 -> -0.15890486 | H10: NA | J10: =+E10-F10 -> -6.3671926 | K10: =+J10/F10 -> -0.15890486
A11: 4 | B11: Return on Equity | C11: Profit after tax | D11: Average Shareholder's Equity | E11: =+'Ratio Working'!C11/'Ratio Working'!C12 -> 0.44067333 | F11: =+'Ratio Working'!D11/'Ratio Working'!D12 -> 0.9190446 | G11: =+K11 -> -0.52050931 | H11: Due to increase in share holders Equity | J11: =+E11-F11 -> -0.47837127 | K11: =+J11/F11 -> -0.52050931
A12: 5 | B12: Inventory Turnover Ratio | C12: Total Turnover | D12: Average Inventory | E12: =+'Ratio Working'!C13/'Ratio Working'!C19 -> 17.3463 | F12: =+'Ratio Working'!D13/'Ratio Working'!D19 -> 5.9686718 | G12: =+K12 -> 1.9062246 | H12: Due to increase in Revenue and decrease in Inventory leval | J12: =+E12-F12 -> 11.377629 | K12: =+J12/F12 -> 1.9062246
A13: 6 | B13: Trade Receivable Turnover Ratio | C13: Total Turnover | D13: Average Trade Receivable | E13: =+'Ratio Working'!C13/'Ratio Working'!C14 -> 2.845687 | F13: =+'Ratio Working'!D13/'Ratio Working'!D14 -> 6.8923138 | G13: =+K13 -> -0.58712167 | H13: Due to increase in Trade receivables as compared to revenue from operations | J13: =+E13-F13 -> -4.0466268 | K13: =+J13/F13 -> -0.58712167
A14: 7 | B14: Trade Payable Turnover Ratio | C14: Total Purchase | D14: Average Trade Payable | E14: =+'Ratio Working'!C15/'Ratio Working'!C16 -> 4.3749964 | F14: =+'Ratio Working'!D15/'Ratio Working'!D16 -> 8.3506817 | G14: =+K14 -> -0.47609111 | H14: Due to increase in trade payables | J14: =+E14-F14 -> -3.9756853 | K14: =+J14/F14 -> -0.47609111
A15: 8 | B15: Net Capital Turnover Ratio | C15: Total Turnover | D15: Net Working Capital | E15: =+'Ratio Working'!C13/'Ratio Working'!C17 -> 3.4428471 | F15: =+'Ratio Working'!D13/'Ratio Working'!D17 -> 10.880072 | G15: =+K15 -> -0.68356393 | H15: Due to increase in net working capital | J15: =+E15-F15 -> -7.4372246 | K15: =+J15/F15 -> -0.68356393
A16: 9 | B16: Net Profit Ratio | C16: Net Profit | D16: Total Turnover | E16: =+'Ratio Working'!C11/'Ratio Working'!C13 -> 0.093740467 | F16: =+'Ratio Working'!D11/'Ratio Working'!D13 -> 0.064107978 | G16: =+K16 -> 0.4622278 | H16: Due to increase in Net Profit | J16: =+E16-F16 -> 0.029632489 | K16: =+J16/F16 -> 0.4622278
A17: 10 | B17: Return on Capital Employed | C17: EBIT | D17: Total Assets - Total Current Liabilities | E17: =+'Ratio Working'!C21/'Ratio Working'!C23 -> 0.38013643 | F17: =+'Ratio Working'!D21/'Ratio Working'!D23 -> 0.89804095 | G17: =+K17 -> -0.57670479 | H17: Due to increase in equity share capital and total debts | J17: =+E17-F17 -> -0.51790452 | K17: =+J17/F17 -> -0.57670479
A18: 11 | B18: Return on Investment | C18: Income Generated from Investment | D18: Time Weighted average Investment | E18: NA | F18: NA | G18: NA | H18: NA
A20: =+[3]Ratio!$A$22 -> As Per our Report of even date Attached
A22: =+[3]Ratio!$A$24 -> For S.P.P & Co | E22: =+BS!C45 -> For and On behalf of the Board of Directors of
A23: =+[3]Ratio!$A$25 -> Chartered Accountants | E23: =+BS!C46 -> PROGEN RENEWABLES LIMITED
A24: =+[3]Ratio!$A$26 -> Firm Registration Number: 011059S
A28: =+[3]Ratio!$A$31 -> CA S. Prabhu | E28: =+BS!C51 -> Alfred Vinod Antony | G28: =+BS!E51 -> Veena Jose
A29: =+[3]Ratio!$A$32 -> Partner | E29: =+BS!C52 -> Managing Director | G29: =+BS!E52 -> Director & CFO
A30: =+[3]Ratio!$A$33 -> Membership No: 213598 | E30: =+BS!C53 -> DIN No: 02776734 | G30: =+BS!E53 -> DIN No: 08017313
A31: =+[3]Ratio!$A$34 -> UDIN:
E35: =+BS!C58 -> Arvind Jain | G35: =+BS!E58 -> Migael Anitha Christina
A36: PLACE: COIMBATORE | E36: =+BS!C59 -> Whole-time Director | G36: =+BS!E59 -> Company Secretary
A37: DATE: | E37: =+BS!C60 -> DIN No: 07218435 | G37: =+BS!E60 -> M.No. 30946

Sheet Dep - IT Act
A1: =+BS!A1 -> PROGEN RENEWABLES LIMITED
A2: =+BS!A2 -> 87 A, First Floor, Sathy Road, Muniappan Koil Street, Ganapathy, Coimbatore,Tamil Nadu - 641 006.
A3: Depreciation as per Income Tax Act, 1961
A5: S.No | B5: Name of the Assets | C5: W.D.V as on 31st March 2024 | D5: Additions | F5: Deletions | G5: Depreciable Value | H5: Rate of Dep | I5: Dep Amt | J5: W.D.V as on 31st March 2025
D6: Less than 180 Days | E6: More than 180 Days
A8: 1 | B8: Computer & Software | C8: 430592 | D8: 378699 | E8: 332550 | F8: 0 | G8: =+C8+D8+E8-F8 -> 1141841 | H8: 0.4 | I8: =ROUND((D8*H8*0.5)+(E8*H8)+(C8*H8),0) -> 380997 | J8: =+G8-I8 -> 760844
A9: 2 | B9: Plant & Machinery | C9: 6272855 | D9: 2987265 | E9: 2451758 | F9: 0 | G9: =+C9+D9+E9-F9 -> 11711878 | H9: 0.15 | I9: =ROUND((D9*H9*0.5)+(E9*H9)+(C9*H9),0) -> 1532737 | J9: =+G9-I9 -> 10179141
A10: 3 | B10: Furniture | C10: 848986 | D10: 3001040 | E10: 9153 | F10: 0 | G10: =+C10+D10+E10-F10 -> 3859179 | H10: 0.1 | I10: =ROUND((D10*H10*0.5)+(E10*H10)+(C10*H10),0) -> 235866 | J10: =+G10-I10 -> 3623313
B12: Total | C12: =SUM(C7:C11) -> 7552433 | D12: =SUM(D7:D11) -> 6367004 | E12: =SUM(E7:E11) -> 2793461 | F12: =SUM(F7:F11) -> 0 | G12: =SUM(G7:G11) -> 16712898 | I12: =SUM(I7:I11) -> 2149600 | J12: =SUM(J7:J11) -> 14563298

Sheet Ratio Working
A1: =+BS!A1 -> PROGEN RENEWABLES LIMITED
A2: Ratio Analysis Numerator & Denominator Calculation :-
A4: S.No | B4: Particulars | C4: 31st March 2025 | D4: 31st March, 2024 | E4: 31st March, 2023
A5: 1 | B5: Current Assets | C5: =SUM(BS!D34+BS!D35+BS!D36+BS!D37+BS!D38) -> 922269024 | D5: =SUM(BS!E34+BS!E35+BS!E36+BS!E37+BS!E38) -> 448884962 | E5: =SUM(BS!G34+BS!G35+BS!G36+BS!G37+BS!G38) -> 425426831
A6: 2 | B6: Current Liabilities | C6: =SUM(BS!D18+BS!D19+BS!D20+BS!D21) -> 530939196 | D6: =SUM(BS!E18+BS!E19+BS!E20+BS!E21) -> 346254265 | E6: =SUM(BS!G18+BS!G19+BS!G20+BS!G21) -> 395178874
A7: 3 | B7: Total Debt | C7: =+BS!D13+BS!D18 -> 62572534 | D7: =+BS!E13+BS!E18 -> 40603051 | E7: =+BS!G13+BS!G18 -> 13164484
A8: 4 | B8: Shareholder's Equity | C8: =SUM(BS!D9+BS!D10) -> 452910231 | D8: =SUM(BS!E9+BS!E10) -> 120282963 | E8: =SUM(BS!G9+BS!G10) -> 35498048
A9: 5 | B9: Earnings Available for Debt Service | C9: =+'P&L'!D25-'P&L'!D27+'Notes-P&L'!C75+'Notes-P&L'!C65 -> 128847674 | D9: =+'P&L'!E25-'P&L'!E27+'Notes-P&L'!D75+'Notes-P&L'!D65 -> 83369165 | E9: =+'P&L'!F25+'Notes-P&L'!E65+'Notes-P&L'!E72 -> 16183269
A10: 6 | B10: Debt Service | C10: =+'Notes-P&L'!C65+'Notes - '!D59 -> 3823144 | D10: =+'Notes-P&L'!D65+'Notes - '!F59 -> 2080629 | E10: =+'Notes-P&L'!E65+'Notes - '!H59 -> 1218909
A11: 7 | B11: Net Profit After Tax | C11: =+'P&L'!D33 -> 126295478 | D11: =+'P&L'!E33 -> 71584849 | E11: =+'P&L'!F33 -> 14909394
A12: 8 | B12: Average Shareholder's Equity | C12: =ROUND(((C8+D8)/2),0) -> 286596597 | D12: =ROUND(((D8+E8)/2),0) -> 77890506 | E12: 0
A13: 9 | B13: Total Turnover | C13: =+'P&L'!D9 -> 1347288769 | D13: =+'P&L'!E9 -> 1116629346 | E13: =+'P&L'!F9 -> 565057844
A14: 10 | B14: Average Trade Receivable | C14: =ROUND(((BS!E35+BS!D35)/2),0) -> 473449380 | D14: =ROUND(((BS!G35+BS!E35)/2),0) -> 162010810 | E14: 0
A15: 11 | B15: Total Purchase | C15: =+'P&L'!D11 -> 713272184 | D15: =+'P&L'!E11 -> 690532439 | E15: =+'P&L'!F11 -> 321635156
A16: 12 | B16: Average Trade Payable | C16: =ROUND(((BS!D19+BS!E19)/2),0) -> 163033778 | D16: =ROUND(((BS!G19+BS!E19)/2),0) -> 82691745 | E16: 0
A17: 13 | B17: Net Working Capital | C17: =+C5-C6 -> 391329828 | D17: =+D5-D6 -> 102630697 | E17: =+E5-E6 -> 30247957
A18: 14 | B18: Inventories | C18: =+BS!D34 -> 38325985 | D18: =+BS!E34 -> 117014200 | E18: =+BS!G34 -> 257149228
A19: 15 | B19: Average Inventories | C19: =ROUND(((C18+D18)/2),0) -> 77670093 | D19: =ROUND(((D18+E18)/2),0) -> 187081714 | E19: 0
A20: 16 | B20: EBITDA | C20: =+'P&L'!D25+'P&L'!D15+'Notes-P&L'!C65+'Notes-P&L'!C66 -> 175278370 | D20: =+'P&L'!E25+'P&L'!E15+'Notes-P&L'!D65+'Notes-P&L'!D66 -> 111144247 | E20: =+'P&L'!F25+'P&L'!F15+'Notes-P&L'!E65+'Notes-P&L'!E66 -> 16183269
A21: 17 | B21: EBIT | C21: =+'P&L'!D25+'Notes-P&L'!C65+'Notes-P&L'!C66 -> 173465360 | D21: =+'P&L'!E25+'Notes-P&L'!D65+'Notes-P&L'!D66 -> 110064259 | E21: =+'P&L'!F25+'Notes-P&L'!E65 -> 15277954
A22: 18 | B22: Total Assets | C22: =+BS!D39 -> 987263149 | D22: =+BS!E39 -> 468814666 | E22: =+BS!G39 -> 433875966
A23: 19 | B23: Total Assets - Total Current Liabilities | C23: =+C22-C6 -> 456323953 | D23: =+D22-D6 -> 122560401 | E23: =+E22-E6 -> 38697092
A24: 20 | B24: Income Generated from Investment | C24: 0 | D24: 0 | E24: 0
A25: 20 | B25: Time Weighted average Investment | C25: 0 | D25: 0 | E25: 0

Sheet SC & SD
A1: =+'Note 4 - SOCES'!A1:G1 -> PROGEN RENEWABLES LIMITED | F1: =+A1 -> PROGEN RENEWABLES LIMITED | K1: PROGEN RENEWABLES LIMITED | P1: PROGEN RENEWABLES LIMITED | U1: PROGEN RENEWABLES LIMITED
A2: =+'Note 4 - SOCES'!A2:G2 -> Notes Forming Part of the Financial Statements for the year ended 31th March 2025 | F2: =+A2 -> Notes Forming Part of the Financial Statements for the year ended 31th March 2025 | K2: Notes Forming Part of the Financial Statements for the year ended 31th March 2025 | P2: Notes Forming Part of the Financial Statements for the year ended 31th March 2025 | U2: Notes Forming Part of the Financial Statements for the year ended 31th March 2025
A3: =+'Note 4 - SOCES'!#REF! -> #REF! | F3: =+A3 -> #REF! | K3: All figures are showing in Rs. 000's unless otherwise specified | P3: All figures are showing in Rs. 000's unless otherwise specified | U3: All figures are showing in Rs. 000's unless otherwise specified
A5: Sub Note: 6.2 Details of Sundry Creditors - Non MSME Creditors | F5: Sub Note: 6.3 Details of Sundry Creditors - MSME Creditors | K5: Sub Note: 15.1 Details of Advance to Supplier | P5: Sub Note: 13.2 Details of Sundry Debtors | U5: Sub Note: 7.1 Details of Advance from Customers
A6: S.No | B6: Name of the Parties | C6: For the year ended March 31, 2025 | D6: For the year ended March 31, 2024 | F6: =+A6 -> S.No | G6: =+B6 -> Name of the Parties | H6: For the year ended March 31, 2025 | I6: For the year ended March 31, 2024 | K6: S.No | L6: Name of the Parties | M6: For the year ended March 31, 2025 | N6: For the year ended March 31, 2024 | P6: S.No | Q6: Name of the Parties | R6: =+M6 -> For the year ended March 31, 2025 | S6: =+N6 -> For the year ended March 31, 2024 | U6: S.No | V6: Name of the Parties | W6: =+R6 -> For the year ended March 31, 2025 | X6: =+S6 -> For the year ended March 31, 2024
A7: 1 | B7: Erin Systems | C7: 55899 | D7: 56430 | F7: 1 | G7: Akshaya Technologies | H7: 84468 | I7: 0 | K7: 1 | L7: Aarathya S_ FD | M7: 82832 | N7: 0 | P7: 1 | Q7: Angalakshmi Spinning Mill | R7: 26133503 | S7: 0 | U7: 1 | V7: KKP Wind Farms Private Limited | W7: 0 | X7: 100632320
A8: 2 | B8: 4K Infra Solutions | C8: 31313434 | D8: 16423736 | F8: 2 | G8: Cikit Electricals & Technologies India Private Limited | H8: 3877 | I8: 12553 | K8: 2 | L8: Aathavan Construction | M8: 2200000 | N8: 0 | P8: 2 | Q8: Angammal Spinners | R8: 20397777 | S8: 0 | U8: 2 | V8: Thamara Green Powers Private Limited | W8: 0 | X8: 1000000
A9: 3 | B9: Air India Limited - Maharashtra | C9: 3750 | D9: 0 | F9: 3 | G9: D.S Electricals | H9: 248401 | I9: 0 | K9: 3 | L9: Aatithyaa Techno India Private Limited | M9: 0 | N9: 1185284 | P9: 3 | Q9: Annamalaiyar Mills Private Limited | R9: 0 | S9: 123996 | U9: 3 | V9: Propel Industries Private Limited | W9: 15912899 | X9: 0
A10: 4 | B10: Amptech Power Transformers | C10: 0 | D10: 20650 | F10: 4 | G10: Sunchaser Structures Private Limited | H10: 5824805 | I10: 0 | K10: 4 | L10: ABV And Company | M10: 5500 | N10: 21000 | P10: 4 | Q10: Annamalaiyar Spinners | R10: 0 | S10: 628169 | U10: 4 | V10: Shivanjali Green Energy Private Limited | W10: 0 | X10: 1000000
A11: 5 | B11: A M Vinoth Earth Movers_Gowtham | C11: 49847 | D11: 0 | F11: 5 | G11: Vesat Renewables Private Limited | H11: 161460 | I11: 179920 | K11: 5 | L11: AD Dot | M11: 88202 | N11: 0 | P11: 5 | Q11: Annamalaiyar Spinners Private Limited | R11: 0 | S11: 136468 | U11: 5 | V11: Sunland Green Energy Private Limited | W11: 857143 | X11: 0
A12: 6 | B12: Aswatha Energy Solutions | C12: 0 | D12: 534229 | F12: 6 | G12: Viridis Engineering India Private Limited | H12: 0 | I12: 917064 | K12: 6 | L12: Aittar K _50MW Land | M12: 100000 | N12: 0 | P12: 6 | Q12: Best Fabrics | R12: 11000000 | S12: 0 | U12: 6 | V12: Vishmayaa Energy Private Limited | W12: 0 | X12: 1000000
A13: 7 | B13: Benaka Cargo Movers | C13: 0 | D13: 10000 | F13: 7 | G13: Strumento Technologies India Private Limited | H13: 481520 | I13: 88020 | K13: 7 | L13: Alu - Tech Engineering | M13: 0 | N13: 54869 | P13: 7 | Q13: Dhakshan Textiles Private Limited | R13: 0 | S13: 673248 | U13: 7 | V13: Adhilakshmi Spinning Mills Private Limited | W13: 16400000 | X13: 0
A14: 8 | B14: Birdscale Technology And Services Private Limited | C14: 0 | D14: 35700 | F14: 8 | G14: Shree Shara Steels And Alloys | H14: 253127 | I14: 737885 | K14: 8 | L14: Ananta Renewables | M14: 0 | N14: 3750000 | P14: 8 | Q14: Dharan Hospital | R14: 0 | S14: 12435159 | U14: 8 | V14: Arunaagold Tex Corporate Private Limited | W14: 2400000 | X14: 0
A15: 9 | B15: Bright Electricals | C15: 0 | D15: 15500 | F15: 9 | G15: Solar Mounting System Solutions | H15: 4460 | I15: 1111 | K15: 9 | L15: Annamalai Pattani_ 50MW Kanjanur Land | M15: 270000 | N15: 0 | P15: 9 | Q15: Enkay Textile | R15: 0 | S15: 854333 | U15: 9 | V15: Arunachala Spinning Mills India Private Limited | W15: 2594258 | X15: 594258
A16: 10 | B16: Cail Holdings | C16: 465000 | D16: 0 | F16: 10 | G16: Shyam Saran And Associates | H16: 90900 | I16: 85950 | K16: 10 | L16: Arrow Marketing | M16: 0 | N16: 2878 | P16: 10 | Q16: Euphoria Green Technologies - Chennai | R16: 0 | S16: 7240344 | U16: 10 | V16: Christ Vidhyanikethan School | W16: 1800000 | X16: 1800000
A17: 11 | B17: Confident Automation | C17: 0 | D17: 35164 | F17: 11 | G17: Newenergie Renewables Private Limited | H17: 10311291 | I17: 0 | K17: 11 | L17: Aruldoss_50MW Land | M17: 500000 | N17: 0 | P17: 11 | Q17: Euphoria Green Technologies - Odisa | R17: 0 | S17: 72450 | U17: 11 | V17: Dev Nature Power Private Limited | W17: 500000 | X17: 0
A18: 12 | B18: Devi Crane Service | C18: 0 | D18: 3200 | F18: 12 | G18: I.P.L.Products | H18: 0 | I18: 1250 | K18: 12 | L18: Arunadevi S_15MW Pottapalayam Land | M18: 834000 | N18: 0 | P18: 12 | Q18: Igen Solars | R18: 0 | S18: 350400 | U18: 12 | V18: Dinesh Textiles | W18: 2000000 | X18: 0
... A36: 30 | B36: Progen Energy Solutions | C36: 0 | D36: 17417404 | F36: 30 | G36: Sami Power Solution | H36: 36260310 | I36: 4664940 | K36: 30 | L36: Future Green Enterprises | M36: 12119104 | N36: 0 | P36: 30 | Q36: Ramesh Iron & Steel Company India Private Limited | R36: 0 | S36: 423000 | U36: 30 | V36: Jothi B Sen | W36: 0 | X36: 150000
A37: 31 | B37: Raj Manpower Solutions | C37: 44231 | D37: 44231 | G37: Total | H37: =SUM(H7:H36) -> 121985514 | I37: =SUM(I7:I36) -> 42743148 | K37: 31 | L37: Gemini Electric Corporation | M37: 37037 | N37: 1850137 | P37: 31 | Q37: Senkarvel Renewables Private Limited | R37: 12894384 | S37: 21394384 | U37: 31 | V37: Cyneric Technologies | W37: 500000 | X37: 0
A38: 32 | B38: Ranis Grand | C38: 6569 | D38: 0 | K38: 32 | L38: Goldi Sun Private Limited | M38: 1758328 | N38: 0 | P38: 32 | Q38: Sheemat Fabricaters | R38: 0 | S38: 373482 | U38: 32 | V38: Rayanesh Solar | W38: 140000 | X38: 0
A39: 33 | B39: Raptor Technologies India Private Limited | C39: 0 | D39: 14892 | K39: 33 | L39: Hari Basker R | M39: 3500 | N39: 0 | P39: 33 | Q39: Shri Sakthivel Impex Private Limited | R39: 0 | S39: 755030 | U39: 33 | V39: Athiyan Global Textiles Private Limited | W39: 5600000 | X39: 0
A40: 34 | B40: Rayaansh Solar | C40: 0 | D40: 46187 | K40: 34 | L40: Iconic Power | M40: 100000 | N40: 0 | P40: 34 | Q40: Soura Natural Energy Solutions India Private Limited | R40: 0 | S40: 43558
A41: 35 | B41: R.C.R Earh Movers _Veepur Manikandan | C41: 0 | D41: 43659 | K41: 35 | L41: KNK Steels | M41: 244658 | N41: 0 | P41: 35 | Q41: Sree Katteri Textiles Private Limited | R41: 0 | S41: 12426297 | V41: Total | W41: =SUM(W7:W40) -> 86306370 | X41: =SUM(X7:X40) -> 118766471
